Workbook
Name a: #REF!
Name a: Demande_alea!$D1
Name b: #REF!
Name b: Demande_alea!$E1
Name d: #REF!
Name d: Demande_alea!$H1
Name f: #REF!
Name f: Demande_alea!$F1
Name k: #REF!
Name k: Demande_alea!$G1
Name s: #REF!
Name s: Demande_alea!$I1
Name t: #REF!
Name t: Demande_alea!A$2

Sheet Account
A1: <Nom> | B1: Account | Q1: /Fin/
Q2: /Fin/
A3: <Process> | B3: résultat courant | C3: cumulative result | D3: cumulative result | Q3: /Fin/
A4: emprunt 0,4% par semaine | B4: 1 | C4: -1 | D4: -0.204 | Q4: /Fin/
A5: <Periode_Debut> | B5: 0 | C5: 0 | D5: 1 | Q5: /Fin/
A6: <Periode_Prolongement> | B6: 0 | C6: 0 | D6: 4 | Q6: /Fin/
A7: <Source> | B7: Account | C7: Account | D7: Account | Q7: /Fin/
Q8: /Fin/
A9: <Etat des lieux> | B9: <Minimal> | C9: <Maximal> | D9: 0 | E9: 1 | F9: 2 | G9: 3 | H9: 4 | I9: 5 | J9: 6 | K9: 7 | L9: 8 | M9: 9 | N9: 10 | O9: 11 | P9: 12 | Q9: /Fin/
A10: cumulative result | B10: -1000000000000 | C10: =-B10 -> 1000000000000 | D10: 0 | E10: 11454.5 | F10: -55172 | G10: -90658 | H10: -94258 | I10: -94258 | J10: -94258 | K10: -94258 | L10: -94258 | M10: -94258 | N10: -94258 | O10: -94258 | P10: -94258 | Q10: /Fin/
A11: cumulative CO2 | B11: =B10 -> -1000000000000 | C11: =-B11 -> 1000000000000 | D11: 0 | E11: 340808.32 | F11: 722862.96 | Q11: /Fin/
Q12: /Fin/
A13: /Fin/ | B13: /Fin/ | C13: /Fin/ | D13: /Fin/ | E13: /Fin/ | F13: /Fin/ | G13: /Fin/ | H13: /Fin/ | I13: /Fin/ | J13: /Fin/ | K13: /Fin/ | L13: /Fin/ | M13: /Fin/ | N13: /Fin/ | O13: /Fin/ | P13: /Fin/ | Q13: /Fin/

Sheet Arnhem
A1: <Nom> | B1: Arnhem factory | E1: Période | F1: 1 | S1: /Fin/
S2: /Fin/
A3: <Process> | B3: nectar (pallet) | C3: nectar (vat) | D3: pack (batch) | E3: Time not used | F3: Time not used | G3: production cost (wages excluded) | H3: production cost (wages excluded) | I3: CO2 production | J3: CO2 production | K3: cost of nectar pallets storage | L3: cost of nectar vats storage | M3: pack storage cost | N3: cumulative result | O3: cumulative result | P3: cumulative result | Q3: cumulative CO2 | S3: /Fin/
A4: Nectar packaging | B4: 30 | C4: -1 | D4: -1 | E4: -20 | F4: =-E4 -> 20 | G4: 100 | H4: =-G4 -> -100 | I4: 500 | J4: =-I4 -> -500 | K4: =18000*0.02 -> 360 | L4: -330 | M4: =1000*0.02*D4 -> -20 | N4: =-G4 -> -100 | O4: =-K4 -> -360 | P4: =-(L4+M4) -> 350 | Q4: =I4 -> 500 | S4: /Fin/
A5: <Periode_Debut> | B5: 0 | C5: 0 | D5: 0 | E5: 0 | F5: 1 | G5: 0 | H5: 1 | I5: 0 | J5: 1 | K5: 1 | L5: 0 | M5: 0 | N5: 0 | O5: 1 | P5: 0 | Q5: 0 | S5: /Fin/
A6: <Periode_Prolongement> | B6: 0 | C6: 0 | D6: 0 | E6: 0 | F6: 0 | G6: 0 | H6: 0 | I6: 0 | J6: 0 | K6: 0 | L6: 0 | M6: 0 | N6: 0 | O6: 20 | P6: 20 | Q6: 0 | S6: /Fin/
A7: <Source> | B7: Arnhem factory | C7: Arnhem factory | D7: Arnhem factory | E7: Arnhem factory | F7: Arnhem factory | G7: Arnhem factory | H7: Arnhem factory | I7: Arnhem factory | J7: Arnhem factory | K7: Arnhem factory | L7: Arnhem factory | M7: Arnhem factory | N7: Account | O7: Account | P7: Account | Q7: Account | S7: /Fin/
S8: /Fin/
A9: <Process> | B9: nectar (vat) | C9: concentrate (bin) | D9: puree (bin) | E9: Time not used | F9: Time not used | G9: production cost (wages excluded) | H9: production cost (wages excluded) | I9: CO2 production | J9: CO2 production | K9: cost of nectar vats storage | L9: concentrate storage cost | M9: puree storage cost | N9: cumulative result | O9: cumulative result | P9: cumulative result | Q9: cumulative CO2 | S9: /Fin/
A10: Nectar production | B10: 1 | C10: -1 | D10: -5 | E10: -100 | F10: =-E10 -> 100 | G10: 300 | H10: =-G10 -> -300 | I10: 2000 | J10: =-I10 -> -2000 | K10: 330 | L10: =64*C10 -> -64 | M10: =2200*0.02*D10 -> -220 | N10: =-G10 -> -300 | O10: =-K10 -> -330 | P10: =-(L10+M10) -> 284 | Q10: =I10 -> 2000 | S10: /Fin/
A11: <Periode_Debut> | B11: 0 | C11: 0 | D11: 0 | E11: 0 | F11: 1 | G11: 0 | H11: 1 | I11: 0 | J11: 1 | K11: 1 | L11: 0 | M11: 0 | N11: 0 | O11: 1 | P11: 0 | Q11: 0 | S11: /Fin/
A12: <Periode_Prolongement> | B12: 0 | C12: 0 | D12: 0 | E12: 0 | F12: 0 | G12: 0 | H12: 0 | I12: 0 | J12: 0 | K12: 0 | L12: 0 | M12: 0 | N12: 0 | O12: 20 | P12: 20 | Q12: 0 | S12: /Fin/
A13: <Source> | B13: Arnhem factory | C13: Arnhem factory | D13: Arnhem factory | E13: Arnhem factory | F13: Arnhem factory | G13: Arnhem factory | H13: Arnhem factory | I13: Arnhem factory | J13: Arnhem factory | K13: Arnhem factory | L13: Arnhem factory | M13: Arnhem factory | N13: Account | O13: Account | P13: Account | Q13: Account | S13: /Fin/
S14: /Fin/
A15: <Process> | B15: staff | C15: Time not used | D15: Hiring cost | E15: Hiring cost | F15: wages cost | G15: cumulative result | H15: cumulative result | S15: /Fin/
A16: Hiring | B16: 1 | C16: 150 | D16: 2000 | E16: =-D16 -> -2000 | F16: 3000 | G16: =-D16 -> -2000 | H16: =-F16 -> -3000 | S16: /Fin/
A17: <Periode_Debut> | B17: 0 | C17: 1 | D17: 0 | E17: 1 | F17: 1 | G17: 0 | H17: 1 | S17: /Fin/
A18: <Periode_Prolongement> | B18: 0 | C18: 0 | D18: 0 | E18: 0 | F18: 0 | G18: 0 | H18: 20 | S18: /Fin/
A19: <Source> | B19: Arnhem factory | C19: Arnhem factory | D19: Arnhem factory | E19: Arnhem factory | F19: Arnhem factory | G19: Account | H19: Account | S19: /Fin/
S20: /Fin/
A21: <Process> | B21: staff | C21: Time not used | D21: Laying-off cost | E21: Laying-off cost | F21: wages cost | G21: cumulative result | H21: cumulative result | S21: /Fin/
A22: Laying-off | B22: -1 | C22: -150 | D22: 2000 | E22: =-D22 -> -2000 | F22: -3000 | G22: =-D22 -> -2000 | H22: =-F22 -> 3000 | S22: /Fin/
A23: <Periode_Debut> | B23: 0 | C23: 1 | D23: 0 | E23: 1 | F23: 1 | G23: 0 | H23: 1 | S23: /Fin/
A24: <Periode_Prolongement> | B24: 0 | C24: 0 | D24: 0 | E24: 0 | F24: 0 | G24: 0 | H24: 20 | S24: /Fin/
A25: <Source> | B25: Arnhem factory | C25: Arnhem factory | D25: Arnhem factory | E25: Arnhem factory | F25: Arnhem factory | G25: Account | H25: Account | S25: /Fin/
S26: /Fin/
A27: <Etat des lieux> | B27: <Minimal> | C27: <Maximal> | D27: 0 | E27: 1 | F27: 2 | G27: 3 | H27: 4 | I27: 5 | J27: 6 | K27: 7 | L27: 8 | M27: 9 | N27: 10 | O27: 11 | P27: 12 | S27: /Fin/
A28: nectar (pallet) | B28: 0 | C28: 750 | D28: 300 | E28: 472 | F28: 282 | S28: /Fin/
A29: nectar (vat) | B29: 0 | C29: 160 | D29: 10 | E29: 7 | F29: 7 | S29: /Fin/
A30: cordial (pallet) | B30: 0 | C30: 750 | E30: 0 | F30: 0 | S30: /Fin/
A31: concentrate (bin) | B31: 0 | C31: 90 | D31: 10 | E31: 13 | F31: 11 | G31: 5 | S31: /Fin/
A32: puree (bin) | B32: 0 | C32: 90 | D32: 50 | E32: 65 | F32: 90 | G32: 60 | S32: /Fin/
A33: pack (batch) | B33: 0 | C33: 90 | D33: 10 | E33: 20 | F33: 23 | S33: /Fin/
A34: staff | B34: 0 | C34: 20 | D34: 6 | E34: 6 | F34: 6 | S34: /Fin/
A35: Time not used | B35: 0 | C35: 1000000000 | D35: 900 | E35: 0 | F35: 60 | G35: 840 | S35: /Fin/
A36: production cost (wages excluded) | B36: -1000000000 | C36: 1000000000 | E36: 3100 | F36: 2800 | G36: -2800 | S36: /Fin/
A37: cost of nectar pallets storage | B37: -1000000000 | C37: 1000000000 | E37: 2064 | F37: 864 | G37: 2520 | S37: /Fin/
A38: cost of nectar vats storage | B38: -1000000000 | C38: 1000000000 | E38: 0 | F38: 0 | G38: 2310 | S38: /Fin/
A39: cost of cordial pallets storage | B39: -1000000000 | C39: 1000000000 | E39: 0 | F39: 0 | S39: /Fin/
A40: concentrate storage cost | B40: -1000000000 | C40: 1000000000 | E40: 192 | F40: 384 | G40: 320 | H40: 320 | S40: /Fin/
...

Sheet Vesoul
A1: <Nom> | B1: Vesoul factory | E1: Période | F1: 1 | S1: /Fin/
S2: /Fin/
A3: <Process> | B3: cordial (pallet) | C3: cordial (vat) | D3: bottle (batch) | E3: Time not used | F3: Time not used | G3: production cost (wages excluded) | H3: production cost (wages excluded) | I3: CO2 production | J3: CO2 production | K3: cost of cordial pallets storage | L3: cost of cordial vats storage | M3: bottles storage cost | N3: cumulative result | O3: cumulative result | P3: cumulative result | Q3: cumulative CO2 | S3: /Fin/
A4: Cordial packaging | B4: 20 | C4: -1 | D4: -1 | E4: -20 | F4: =-E4 -> 20 | G4: 100 | H4: =-G4 -> -100 | I4: 500 | J4: =-I4 -> -500 | K4: 380 | L4: -310 | M4: -60 | N4: =-G4 -> -100 | O4: =-K4 -> -380 | P4: =-(L4+M4) -> 370 | Q4: =I4 -> 500 | S4: /Fin/
A5: <Periode_Debut> | B5: 0 | C5: 0 | D5: 0 | E5: 0 | F5: 1 | G5: 0 | H5: 1 | I5: 0 | J5: 1 | K5: 1 | L5: 0 | M5: 0 | N5: 0 | O5: 1 | P5: 0 | Q5: 0 | S5: /Fin/
A6: <Periode_Prolongement> | B6: 0 | C6: 0 | D6: 0 | E6: 0 | F6: 0 | G6: 0 | H6: 0 | I6: 0 | J6: 0 | K6: 0 | L6: 0 | M6: 0 | N6: 0 | O6: 20 | P6: 20 | Q6: 0 | S6: /Fin/
A7: <Source> | B7: Vesoul factory | C7: Vesoul factory | D7: Vesoul factory | E7: Vesoul factory | F7: Vesoul factory | G7: Vesoul factory | H7: Vesoul factory | I7: Vesoul factory | J7: Vesoul factory | K7: Vesoul factory | L7: Vesoul factory | M7: Vesoul factory | N7: Account | O7: Account | P7: Account | Q7: Account | S7: /Fin/
S8: /Fin/
A9: <Process> | B9: cordial (vat) | C9: concentrate (bin) | D9: sugar (tonne) | E9: Time not used | F9: Time not used | G9: production cost (wages excluded) | H9: production cost (wages excluded) | I9: CO2 production | J9: CO2 production | K9: cost of cordial vats storage | L9: concentrate storage cost | M9: sugar storage cost | N9: cumulative result | O9: cumulative result | P9: cumulative result | Q9: cumulative CO2 | S9: /Fin/
A10: Cordial production | B10: 1 | C10: -4 | D10: -1 | E10: -100 | F10: =-E10 -> 100 | G10: 300 | H10: =-G10 -> -300 | I10: 2000 | J10: =-I10 -> -2000 | K10: 310 | L10: =64*C10 -> -256 | M10: =8*D10 -> -8 | N10: =-G10 -> -300 | O10: =-K10 -> -310 | P10: =-(L10+M10) -> 264 | Q10: =I10 -> 2000 | S10: /Fin/
A11: <Periode_Debut> | B11: 0 | C11: 0 | D11: 0 | E11: 0 | F11: 1 | G11: 0 | H11: 1 | I11: 0 | J11: 1 | K11: 1 | L11: 0 | M11: 0 | N11: 0 | O11: 1 | P11: 0 | Q11: 0 | S11: /Fin/
A12: <Periode_Prolongement> | B12: 0 | C12: 0 | D12: 0 | E12: 0 | F12: 0 | G12: 0 | H12: 0 | I12: 0 | J12: 0 | K12: 0 | L12: 0 | M12: 0 | N12: 0 | O12: 20 | P12: 20 | Q12: 0 | S12: /Fin/
A13: <Source> | B13: Vesoul factory | C13: Vesoul factory | D13: Vesoul factory | E13: Vesoul factory | F13: Vesoul factory | G13: Vesoul factory | H13: Vesoul factory | I13: Vesoul factory | J13: Vesoul factory | K13: Vesoul factory | L13: Vesoul factory | M13: Vesoul factory | N13: Account | O13: Account | P13: Account | Q13: Account | S13: /Fin/
S14: /Fin/
A15: <Process> | B15: staff | C15: Time not used | D15: Hiring cost | E15: Hiring cost | F15: wages cost | G15: cumulative result | H15: cumulative result | S15: /Fin/
A16: Hiring | B16: 1 | C16: 150 | D16: 2000 | E16: =-D16 -> -2000 | F16: 3000 | G16: =-D16 -> -2000 | H16: =-F16 -> -3000 | S16: /Fin/
A17: <Periode_Debut> | B17: 0 | C17: 1 | D17: 0 | E17: 1 | F17: 1 | G17: 0 | H17: 1 | S17: /Fin/
A18: <Periode_Prolongement> | B18: 0 | C18: 0 | D18: 0 | E18: 0 | F18: 0 | G18: 0 | H18: 20 | S18: /Fin/
A19: <Source> | B19: Vesoul factory | C19: Vesoul factory | D19: Vesoul factory | E19: Vesoul factory | F19: Vesoul factory | G19: Account | H19: Account | S19: /Fin/
S20: /Fin/
A21: <Process> | B21: staff | C21: Time not used | D21: Laying-off cost | E21: Laying-off cost | F21: wages cost | G21: cumulative result | H21: cumulative result | S21: /Fin/
A22: Laying-off | B22: -1 | C22: -150 | D22: 2000 | E22: =-D22 -> -2000 | F22: -3000 | G22: =-D22 -> -2000 | H22: =-F22 -> 3000 | S22: /Fin/
A23: <Periode_Debut> | B23: 0 | C23: 1 | D23: 0 | E23: 1 | F23: 1 | G23: 0 | H23: 1 | S23: /Fin/
A24: <Periode_Prolongement> | B24: 0 | C24: 0 | D24: 0 | E24: 0 | F24: 0 | G24: 0 | H24: 20 | S24: /Fin/
A25: <Source> | B25: Vesoul factory | C25: Vesoul factory | D25: Vesoul factory | E25: Vesoul factory | F25: Vesoul factory | G25: Account | H25: Account | S25: /Fin/
S26: /Fin/
A27: <Etat des lieux> | B27: <Minimal> | C27: <Maximal> | D27: 0 | E27: 1 | F27: 2 | G27: 3 | H27: 4 | I27: 5 | J27: 6 | K27: 7 | L27: 8 | M27: 9 | N27: 10 | O27: 11 | P27: 12 | S27: /Fin/
A28: cordial (pallet) | B28: 0 | C28: 750 | D28: 200 | E28: 304 | F28: 185 | S28: /Fin/
A29: cordial (vat) | B29: 0 | C29: 160 | D29: 10 | E29: 7 | F29: 7 | S29: /Fin/
A30: nectar (pallet) | B30: 0 | C30: 750 | E30: 0 | F30: 0 | S30: /Fin/
A31: concentrate (bin) | B31: 0 | C31: 90 | D31: 40 | E31: 52 | F31: 34 | G31: 10 | S31: /Fin/
A32: sugar (tonne) | B32: 0 | C32: 90 | D32: 10 | E32: 23 | F32: 26 | S32: /Fin/
A33: bottle (batch) | B33: 0 | C33: 90 | D33: 10 | E33: 20 | F33: 23 | S33: /Fin/
A34: staff | B34: 0 | C34: 20 | D34: 6 | E34: 6 | F34: 6 | S34: /Fin/
A35: Time not used | B35: 0 | C35: 1000000000 | D35: 900 | E35: 0 | F35: 60 | G35: 840 | S35: /Fin/
A36: production cost (wages excluded) | B36: -1000000000 | C36: 1000000000 | E36: 3100 | F36: 2800 | G36: -2800 | S36: /Fin/
A37: cost of cordial vats storage | B37: -1000000000 | C37: 1000000000 | E37: 0 | F37: 0 | G37: 2170 | S37: /Fin/
A38: cost of cordial pallets storage | B38: -1000000000 | C38: 1000000000 | E38: 1976 | F38: 855 | G38: 2660 | S38: /Fin/
A39: cost of nectar pallets storage | B39: -1000000000 | C39: 1000000000 | E39: 0 | F39: 0 | S39: /Fin/
A40: concentrate storage cost | B40: -1000000000 | C40: 1000000000 | E40: 768 | F40: 1536 | G40: 640 | H40: 640 | S40: /Fin/
...

Sheet Auckland
A1: <Nom> | B1: Auckland factory | E1: Période | F1: 1 | Q1: /Fin/
Q2: /Fin/
A3: <Process> | B3: concentrate (bin) | C3: puree (bin) | D3: Time not used | E3: Time not used | F3: production cost (wages excluded) | G3: production cost (wages excluded) | H3: CO2 production | I3: CO2 production | J3: concentrate storage cost | K3: puree storage cost | L3: cumulative result | M3: cumulative result | N3: cumulative CO2 | Q3: /Fin/
A4: Purchasing and pression of kiwis | B4: 1 | C4: 4 | D4: -50 | E4: =-D4 -> 50 | F4: 10000 | G4: =-F4 -> -10000 | H4: 10000 | I4: =-H4 -> -10000 | J4: =0.02*3000*B4 -> 60 | K4: =0.02*2000*C4 -> 160 | L4: =-F4 -> -10000 | M4: =-J4-K4 -> -220 | N4: =F4 -> 10000 | Q4: /Fin/
A5: <Periode_Debut> | B5: 0 | C5: 0 | D5: 0 | E5: 1 | F5: 0 | G5: 1 | H5: 0 | I5: 1 | J5: 1 | K5: 1 | L5: 0 | M5: 1 | N5: 0 | Q5: /Fin/
A6: <Periode_Prolongement> | B6: 0 | C6: 0 | D6: 0 | E6: 0 | F6: 0 | G6: 0 | H6: 0 | I6: 0 | J6: 0 | K6: 0 | L6: 0 | M6: 20 | N6: 0 | Q6: /Fin/
A7: <Source> | B7: Auckland factory | C7: Auckland factory | D7: Auckland factory | E7: Auckland factory | F7: Auckland factory | G7: Auckland factory | H7: Auckland factory | I7: Auckland factory | J7: Auckland factory | K7: Auckland factory | L7: Account | M7: Account | N7: Account | Q7: /Fin/
Q8: /Fin/
A9: <Process> | B9: puree (bin) | C9: Puree sale | D9: Puree sale | E9: puree storage cost | F9: cumulative result | G9: cumulative result | Q9: /Fin/
A10: Puree sale | B10: -1 | C10: 2000 | D10: =-C10 -> -2000 | E10: -40 | F10: =C10 -> 2000 | G10: =-E10 -> 40 | Q10: /Fin/
A11: <Periode_Debut> | B11: 0 | C11: 0 | D11: 1 | E11: 1 | F11: 0 | G11: 1 | Q11: /Fin/
A12: <Periode_Prolongement> | B12: 0 | C12: 0 | D12: 0 | E12: 0 | F12: 0 | G12: 20 | Q12: /Fin/
A13: <Source> | B13: Auckland factory | C13: Auckland factory | D13: Auckland factory | E13: Auckland factory | F13: Account | G13: Account | Q13: /Fin/
Q14: /Fin/
A15: <Process> | B15: concentrate (bin) | C15: Concentrate sale | D15: Concentrate sale | E15: concentrate storage cost | F15: cumulative result | G15: cumulative result | Q15: /Fin/
A16: Concentrate sale | B16: -1 | C16: 3000 | D16: =-C16 -> -3000 | E16: -60 | F16: =C16 -> 3000 | G16: =-E16 -> 60 | Q16: /Fin/
A17: <Periode_Debut> | B17: 0 | C17: 0 | D17: 1 | E17: 1 | F17: 0 | G17: 1 | Q17: /Fin/
A18: <Periode_Prolongement> | B18: 0 | C18: 0 | D18: 0 | E18: 0 | F18: 0 | G18: 20 | Q18: /Fin/
A19: <Source> | B19: Auckland factory | C19: Auckland factory | D19: Auckland factory | E19: Auckland factory | F19: Account | G19: Account | Q19: /Fin/
Q20: /Fin/
A21: <Process> | B21: staff | C21: Time not used | D21: Hiring cost | E21: Hiring cost | F21: wages cost | G21: cumulative result | H21: cumulative result | Q21: /Fin/
A22: Hiring | B22: 1 | C22: 150 | D22: 2000 | E22: =-D22 -> -2000 | F22: 3000 | G22: =-D22 -> -2000 | H22: =-F22 -> -3000 | Q22: /Fin/
A23: <Periode_Debut> | B23: 0 | C23: 1 | D23: 0 | E23: 1 | F23: 1 | G23: 0 | H23: 1 | Q23: /Fin/
A24: <Periode_Prolongement> | B24: 0 | C24: 0 | D24: 0 | E24: 0 | F24: 0 | G24: 0 | H24: 20 | Q24: /Fin/
A25: <Source> | B25: Auckland factory | C25: Auckland factory | D25: Auckland factory | E25: Auckland factory | F25: Auckland factory | G25: Account | H25: Account | Q25: /Fin/
Q26: /Fin/
A27: <Process> | B27: staff | C27: Time not used | D27: Laying-off cost | E27: Laying-off cost | F27: wages cost | G27: cumulative result | H27: cumulative result | Q27: /Fin/
A28: Laying-off | B28: -1 | C28: -150 | D28: 2000 | E28: =-D28 -> -2000 | F28: -3000 | G28: =-D28 -> -2000 | H28: =-F28 -> 3000 | Q28: /Fin/
A29: <Periode_Debut> | B29: 0 | C29: 1 | D29: 0 | E29: 1 | F29: 1 | G29: 0 | H29: 1 | Q29: /Fin/
A30: <Periode_Prolongement> | B30: 0 | C30: 0 | D30: 0 | E30: 0 | F30: 0 | G30: 0 | H30: 20 | Q30: /Fin/
A31: <Source> | B31: Auckland factory | C31: Auckland factory | D31: Auckland factory | E31: Auckland factory | F31: Auckland factory | G31: Account | H31: Account | Q31: /Fin/
Q32: /Fin/
Q33: /Fin/
Q34: /Fin/
Q35: /Fin/
A36: <Etat des lieux> | B36: <Minimal> | C36: <Maximal> | D36: 0 | E36: 1 | F36: 2 | G36: 3 | H36: 4 | I36: 5 | J36: 6 | K36: 7 | L36: 8 | M36: 9 | N36: 10 | O36: 11 | P36: 12 | Q36: /Fin/
A37: concentrate (bin) | B37: 0 | C37: 90 | D37: 15 | E37: 15 | F37: 24 | Q37: /Fin/
A38: puree (bin) | B38: 0 | C38: 90 | D38: 60 | E38: 60 | F38: 96 | Q38: /Fin/
A39: staff | B39: 0 | C39: 20 | D39: 5 | E39: 8 | F39: 8 | Q39: /Fin/
A40: Time not used | B40: 0 | C40: 1000000000 | D40: 750 | E40: 0 | F40: 0 | G40: 1200 | Q40: /Fin/
...

Sheet Lorry1
A1: <Nom> | B1: Lorry 1 | E1: Période | F1: 1 | Q1: /Fin/
Q2: /Fin/
A3: <Process> | B3: distance (km) | C3: distance (km) | D3: Time not used | E3: Time not used | F3: transport cost | G3: transport cost | H3: CO2 production | I3: CO2 production | J3: cumulative result | K3: cumulative CO2 | Q3: /Fin/
A4: driving | B4: 1 | C4: -1 | D4: =-B4/60 -> -0.016666667 | E4: =-D4 -> 0.016666667 | F4: 2.5 | G4: =-F4 -> -2.5 | H4: 0.92 | I4: =-H4 -> -0.92 | J4: =-F4 -> -2.5 | K4: =H4 -> 0.92 | Q4: /Fin/
A5: <Periode_Debut> | B5: 0 | C5: 1 | D5: 0 | E5: 1 | F5: 0 | G5: 1 | H5: 0 | I5: 1 | J5: 0 | K5: 0 | Q5: /Fin/
A6: <Periode_Prolongement> | B6: 0 | C6: 0 | D6: 0 | E6: 0 | F6: 0 | G6: 0 | H6: 0 | I6: 0 | J6: 0 | K6: 0 | Q6: /Fin/
A7: <Source> | B7: Lorry 1 | C7: Lorry 1 | D7: Lorry 1 | E7: Lorry 1 | F7: Lorry 1 | G7: Lorry 1 | H7: Lorry 1 | I7: Lorry 1 | J7: Account | K7: Account | Q7: /Fin/
Q8: /Fin/
A9: <Process> | B9: nectar (pallet) | C9: nectar (pallet) | D9: volume (pallet) | E9: weight (tonne) | F9: Time not used | G9: Time not used | H9: cost of nectar pallets storage | I9: cumulative result | Q9: /Fin/
A10: nectar loading | B10: 1 | C10: =-B10 -> -1 | D10: =B10 -> 1 | E10: =0.35*B10 -> 0.35 | F10: -0.03 | G10: =-F10 -> 0.03 | H10: =-12*B10 -> -12 | I10: =-H10 -> 12 | Q10: /Fin/
A11: <Periode_Debut> | B11: 0 | C11: 0 | D11: 0 | E11: 0 | F11: 0 | G11: 1 | H11: 0 | I11: 0 | Q11: /Fin/
A12: <Periode_Prolongement> | B12: 0 | C12: 0 | D12: 0 | E12: 0 | F12: 0 | G12: 0 | H12: 0 | I12: 20 | Q12: /Fin/
A13: <Source> | B13: Lorry 1 | C13: ? | D13: Lorry 1 | E13: Lorry 1 | F13: Lorry 1 | G13: Lorry 1 | H13: ? | I13: Account | Q13: /Fin/
Q14: /Fin/
A15: <Process> | B15: cordial (pallet) | C15: cordial (pallet) | D15: volume (pallet) | E15: weight (tonne) | F15: Time not used | G15: Time not used | H15: cost of cordial pallets storage | I15: cumulative result | Q15: /Fin/
A16: cordial loading | B16: 1 | C16: =-B16 -> -1 | D16: =B16 -> 1 | E16: 0.5 | F16: -0.03 | G16: =-F16 -> 0.03 | H16: =-19*B16 -> -19 | I16: =-H16 -> 19 | Q16: /Fin/
A17: <Periode_Debut> | B17: 0 | C17: 0 | D17: 0 | E17: 0 | F17: 0 | G17: 1 | H17: 0 | I17: 0 | Q17: /Fin/
A18: <Periode_Prolongement> | B18: 0 | C18: 0 | D18: 0 | E18: 0 | F18: 0 | G18: 0 | H18: 0 | I18: 20 | Q18: /Fin/
A19: <Source> | B19: Lorry 1 | C19: ? | D19: Lorry 1 | E19: Lorry 1 | F19: Lorry 1 | G19: Lorry 1 | H19: ? | I19: Account | Q19: /Fin/
Q20: /Fin/
A21: <Process> | B21: nectar (pallet) | C21: nectar (pallet) | D21: volume (pallet) | E21: weight (tonne) | F21: Time not used | G21: Time not used | H21: cost of nectar pallets storage | I21: cumulative result | Q21: /Fin/
A22: nectar unloading | B22: -1 | C22: =-B22 -> 1 | D22: =B22 -> -1 | E22: =0.35*B22 -> -0.35 | F22: -0.03 | G22: =-F22 -> 0.03 | H22: =-12*B22 -> 12 | I22: =-H22 -> -12 | Q22: /Fin/
A23: <Periode_Debut> | B23: 0 | C23: 0 | D23: 0 | E23: 0 | F23: 0 | G23: 1 | H23: 0 | I23: 0 | Q23: /Fin/
A24: <Periode_Prolongement> | B24: 0 | C24: 0 | D24: 0 | E24: 0 | F24: 0 | G24: 0 | H24: 0 | I24: 20 | Q24: /Fin/
A25: <Source> | B25: Lorry 1 | C25: ? | D25: Lorry 1 | E25: Lorry 1 | F25: Lorry 1 | G25: Lorry 1 | H25: ? | I25: Account | Q25: /Fin/
Q26: /Fin/
A27: <Process> | B27: cordial (pallet) | C27: cordial (pallet) | D27: volume (pallet) | E27: weight (tonne) | F27: Time not used | G27: Time not used | H27: cost of cordial pallets storage | I27: cumulative result | Q27: /Fin/
A28: cordial unloading | B28: -1 | C28: =-B28 -> 1 | D28: =B28 -> -1 | E28: -0.5 | F28: -0.03 | G28: =-F28 -> 0.03 | H28: =-19*B28 -> 19 | I28: =-H28 -> -19 | Q28: /Fin/
A29: <Periode_Debut> | B29: 0 | C29: 0 | D29: 0 | E29: 0 | F29: 0 | G29: 1 | H29: 0 | I29: 0 | Q29: /Fin/
A30: <Periode_Prolongement> | B30: 0 | C30: 0 | D30: 0 | E30: 0 | F30: 0 | G30: 0 | H30: 0 | I30: 20 | Q30: /Fin/
A31: <Source> | B31: Lorry 1 | C31: ? | D31: Lorry 1 | E31: Lorry 1 | F31: Lorry 1 | G31: Lorry 1 | H31: ? | I31: Account | Q31: /Fin/
Q32: /Fin/
Q33: /Fin/
A34: <Etat des lieux> | B34: <Minimal> | C34: <Maximal> | D34: 0 | E34: 1 | F34: 2 | G34: 3 | H34: 4 | I34: 5 | J34: 6 | K34: 7 | L34: 8 | M34: 9 | N34: 10 | O34: 11 | P34: 12 | Q34: /Fin/
A35: nectar (pallet) | B35: 0 | C35: 1000000000 | E35: 0 | F35: 0 | Q35: /Fin/
A36: cordial (pallet) | B36: 0 | C36: 1000000000 | E36: 0 | F36: 0 | Q36: /Fin/
A37: volume (pallet) | B37: 0 | C37: 66 | E37: 0 | F37: 0 | Q37: /Fin/
A38: weight (tonne) | B38: 0 | C38: 25 | E38: -3.5527137e-15 | F38: -3.5527137e-15 | Q38: /Fin/
A39: distance (km) | B39: -1000000000 | C39: 1000000000 | E39: 21967 | F39: 22676 | G39: -22676 | Q39: /Fin/
A40: Time not used | B40: 0 | C40: 500 | D40: 500 | E40: 124.88333 | F40: 99.266667 | G40: 400.73333 | Q40: /Fin/
...

Sheet Lorry2
A1: <Nom> | B1: Lorry 2 | E1: Période | F1: 1 | Q1: /Fin/
Q2: /Fin/
A3: <Process> | B3: distance (km) | C3: distance (km) | D3: Time not used | E3: Time not used | F3: transport cost | G3: transport cost | H3: CO2 production | I3: CO2 production | J3: cumulative result | K3: cumulative CO2 | Q3: /Fin/
A4: driving | B4: 1 | C4: -1 | D4: =-B4/60 -> -0.016666667 | E4: =-D4 -> 0.016666667 | F4: 2 | G4: =-F4 -> -2 | H4: 0.92 | I4: =-H4 -> -0.92 | J4: =-F4 -> -2 | K4: =H4 -> 0.92 | Q4: /Fin/
A5: <Periode_Debut> | B5: 0 | C5: 1 | D5: 0 | E5: 1 | F5: 0 | G5: 1 | H5: 0 | I5: 1 | J5: 0 | K5: 0 | Q5: /Fin/
A6: <Periode_Prolongement> | B6: 0 | C6: 0 | D6: 0 | E6: 0 | F6: 0 | G6: 0 | H6: 0 | I6: 0 | J6: 0 | K6: 0 | Q6: /Fin/
A7: <Source> | B7: Lorry 2 | C7: Lorry 2 | D7: Lorry 2 | E7: Lorry 2 | F7: Lorry 2 | G7: Lorry 2 | H7: Lorry 2 | I7: Lorry 2 | J7: Account | K7: Account | Q7: /Fin/
Q8: /Fin/
A9: <Process> | B9: nectar (pallet) | C9: nectar (pallet) | D9: volume (pallet) | E9: weight (tonne) | F9: Time not used | G9: Time not used | H9: cost of nectar pallets storage | I9: cumulative result | Q9: /Fin/
A10: nectar loading | B10: 1 | C10: =-B10 -> -1 | D10: =B10 -> 1 | E10: =0.35*B10 -> 0.35 | F10: -0.03 | G10: =-F10 -> 0.03 | H10: =-12*B10 -> -12 | I10: =-H10 -> 12 | Q10: /Fin/
A11: <Periode_Debut> | B11: 0 | C11: 0 | D11: 0 | E11: 0 | F11: 0 | G11: 1 | H11: 0 | I11: 0 | Q11: /Fin/
A12: <Periode_Prolongement> | B12: 0 | C12: 0 | D12: 0 | E12: 0 | F12: 0 | G12: 0 | H12: 0 | I12: 20 | Q12: /Fin/
A13: <Source> | B13: Lorry 2 | C13: ? | D13: Lorry 2 | E13: Lorry 2 | F13: Lorry 2 | G13: Lorry 2 | H13: ? | I13: Account | Q13: /Fin/
Q14: /Fin/
A15: <Process> | B15: cordial (pallet) | C15: cordial (pallet) | D15: volume (pallet) | E15: weight (tonne) | F15: Time not used | G15: Time not used | H15: cost of cordial pallets storage | I15: cumulative result | Q15: /Fin/
A16: cordial loading | B16: 1 | C16: =-B16 -> -1 | D16: =B16 -> 1 | E16: 0.5 | F16: -0.03 | G16: =-F16 -> 0.03 | H16: =-19*B16 -> -19 | I16: =-H16 -> 19 | Q16: /Fin/
A17: <Periode_Debut> | B17: 0 | C17: 0 | D17: 0 | E17: 0 | F17: 0 | G17: 1 | H17: 0 | I17: 0 | Q17: /Fin/
A18: <Periode_Prolongement> | B18: 0 | C18: 0 | D18: 0 | E18: 0 | F18: 0 | G18: 0 | H18: 0 | I18: 20 | Q18: /Fin/
A19: <Source> | B19: Lorry 2 | C19: ? | D19: Lorry 2 | E19: Lorry 2 | F19: Lorry 2 | G19: Lorry 2 | H19: ? | I19: Account | Q19: /Fin/
Q20: /Fin/
A21: <Process> | B21: nectar (pallet) | C21: nectar (pallet) | D21: volume (pallet) | E21: weight (tonne) | F21: Time not used | G21: Time not used | H21: cost of nectar pallets storage | I21: cumulative result | Q21: /Fin/
A22: nectar unloading | B22: -1 | C22: =-B22 -> 1 | D22: =B22 -> -1 | E22: =0.35*B22 -> -0.35 | F22: -0.03 | G22: =-F22 -> 0.03 | H22: =-12*B22 -> 12 | I22: =-H22 -> -12 | Q22: /Fin/
A23: <Periode_Debut> | B23: 0 | C23: 0 | D23: 0 | E23: 0 | F23: 0 | G23: 1 | H23: 0 | I23: 0 | Q23: /Fin/
A24: <Periode_Prolongement> | B24: 0 | C24: 0 | D24: 0 | E24: 0 | F24: 0 | G24: 0 | H24: 0 | I24: 20 | Q24: /Fin/
A25: <Source> | B25: Lorry 2 | C25: ? | D25: Lorry 2 | E25: Lorry 2 | F25: Lorry 2 | G25: Lorry 2 | H25: ? | I25: Account | Q25: /Fin/
Q26: /Fin/
A27: <Process> | B27: cordial (pallet) | C27: cordial (pallet) | D27: volume (pallet) | E27: weight (tonne) | F27: Time not used | G27: Time not used | H27: cost of cordial pallets storage | I27: cumulative result | Q27: /Fin/
A28: cordial unloading | B28: -1 | C28: =-B28 -> 1 | D28: =B28 -> -1 | E28: -0.5 | F28: -0.03 | G28: =-F28 -> 0.03 | H28: =-19*B28 -> 19 | I28: =-H28 -> -19 | Q28: /Fin/
A29: <Periode_Debut> | B29: 0 | C29: 0 | D29: 0 | E29: 0 | F29: 0 | G29: 1 | H29: 0 | I29: 0 | Q29: /Fin/
A30: <Periode_Prolongement> | B30: 0 | C30: 0 | D30: 0 | E30: 0 | F30: 0 | G30: 0 | H30: 0 | I30: 20 | Q30: /Fin/
A31: <Source> | B31: Lorry 2 | C31: ? | D31: Lorry 2 | E31: Lorry 2 | F31: Lorry 2 | G31: Lorry 2 | H31: ? | I31: Account | Q31: /Fin/
Q32: /Fin/
Q33: /Fin/
A34: <Etat des lieux> | B34: <Minimal> | C34: <Maximal> | D34: 0 | E34: 1 | F34: 2 | G34: 3 | H34: 4 | I34: 5 | J34: 6 | K34: 7 | L34: 8 | M34: 9 | N34: 10 | O34: 11 | P34: 12 | Q34: /Fin/
A35: nectar (pallet) | B35: 0 | C35: 1000000000 | E35: 0 | F35: 0 | Q35: /Fin/
A36: cordial (pallet) | B36: 0 | C36: 1000000000 | E36: 2 | F36: 0 | Q36: /Fin/
A37: volume (pallet) | B37: 0 | C37: 66 | E37: 2 | F37: 0 | Q37: /Fin/
A38: weight (tonne) | B38: 0 | C38: 25 | E38: 1 | F38: 0 | Q38: /Fin/
A39: distance (km) | B39: -1000000000 | C39: 1000000000 | E39: 9539 | F39: 13476 | G39: -13476 | Q39: /Fin/
A40: Time not used | B40: 0 | C40: 250 | D40: 250 | E40: 88.076667 | F40: 11.78 | G40: 238.22 | Q40: /Fin/
...

Sheet Lorry3
A1: <Nom> | B1: Lorry 3 | E1: Période | F1: 1 | Q1: /Fin/
Q2: /Fin/
A3: <Process> | B3: distance (km) | C3: distance (km) | D3: Time not used | E3: Time not used | F3: transport cost | G3: transport cost | H3: CO2 production | I3: CO2 production | J3: cumulative result | K3: cumulative CO2 | Q3: /Fin/
A4: driving | B4: 1 | C4: -1 | D4: =-B4/70 -> -0.014285714 | E4: =-D4 -> 0.014285714 | F4: 1.5 | G4: =-F4 -> -1.5 | H4: 0.8 | I4: =-H4 -> -0.8 | J4: =-F4 -> -1.5 | K4: =H4 -> 0.8 | Q4: /Fin/
A5: <Periode_Debut> | B5: 0 | C5: 1 | D5: 0 | E5: 1 | F5: 0 | G5: 1 | H5: 0 | I5: 1 | J5: 0 | K5: 0 | Q5: /Fin/
A6: <Periode_Prolongement> | B6: 0 | C6: 0 | D6: 0 | E6: 0 | F6: 0 | G6: 0 | H6: 0 | I6: 0 | J6: 0 | K6: 0 | Q6: /Fin/
A7: <Source> | B7: Lorry 3 | C7: Lorry 3 | D7: Lorry 3 | E7: Lorry 3 | F7: Lorry 3 | G7: Lorry 3 | H7: Lorry 3 | I7: Lorry 3 | J7: Account | K7: Account | Q7: /Fin/
Q8: /Fin/
A9: <Process> | B9: nectar (pallet) | C9: nectar (pallet) | D9: volume (pallet) | E9: weight (tonne) | F9: Time not used | G9: Time not used | H9: cost of nectar pallets storage | I9: cumulative result | Q9: /Fin/
A10: nectar loading | B10: 1 | C10: =-B10 -> -1 | D10: =B10 -> 1 | E10: =0.35*B10 -> 0.35 | F10: -0.03 | G10: =-F10 -> 0.03 | H10: =-12*B10 -> -12 | I10: =-H10 -> 12 | Q10: /Fin/
A11: <Periode_Debut> | B11: 0 | C11: 0 | D11: 0 | E11: 0 | F11: 0 | G11: 1 | H11: 0 | I11: 0 | Q11: /Fin/
A12: <Periode_Prolongement> | B12: 0 | C12: 0 | D12: 0 | E12: 0 | F12: 0 | G12: 0 | H12: 0 | I12: 20 | Q12: /Fin/
A13: <Source> | B13: Lorry 3 | C13: ? | D13: Lorry 3 | E13: Lorry 3 | F13: Lorry 3 | G13: Lorry 3 | H13: ? | I13: Account | Q13: /Fin/
Q14: /Fin/
A15: <Process> | B15: cordial (pallet) | C15: cordial (pallet) | D15: volume (pallet) | E15: weight (tonne) | F15: Time not used | G15: Time not used | H15: cost of cordial pallets storage | I15: cumulative result | Q15: /Fin/
A16: cordial loading | B16: 1 | C16: =-B16 -> -1 | D16: =B16 -> 1 | E16: 0.5 | F16: -0.03 | G16: =-F16 -> 0.03 | H16: =-19*B16 -> -19 | I16: =-H16 -> 19 | Q16: /Fin/
A17: <Periode_Debut> | B17: 0 | C17: 0 | D17: 0 | E17: 0 | F17: 0 | G17: 1 | H17: 0 | I17: 0 | Q17: /Fin/
A18: <Periode_Prolongement> | B18: 0 | C18: 0 | D18: 0 | E18: 0 | F18: 0 | G18: 0 | H18: 0 | I18: 20 | Q18: /Fin/
A19: <Source> | B19: Lorry 3 | C19: ? | D19: Lorry 3 | E19: Lorry 3 | F19: Lorry 3 | G19: Lorry 3 | H19: ? | I19: Account | Q19: /Fin/
Q20: /Fin/
A21: <Process> | B21: nectar (pallet) | C21: nectar (pallet) | D21: volume (pallet) | E21: weight (tonne) | F21: Time not used | G21: Time not used | H21: cost of nectar pallets storage | I21: cumulative result | Q21: /Fin/
A22: nectar unloading | B22: -1 | C22: =-B22 -> 1 | D22: =B22 -> -1 | E22: =0.35*B22 -> -0.35 | F22: -0.03 | G22: =-F22 -> 0.03 | H22: =-12*B22 -> 12 | I22: =-H22 -> -12 | Q22: /Fin/
A23: <Periode_Debut> | B23: 0 | C23: 0 | D23: 0 | E23: 0 | F23: 0 | G23: 1 | H23: 0 | I23: 0 | Q23: /Fin/
A24: <Periode_Prolongement> | B24: 0 | C24: 0 | D24: 0 | E24: 0 | F24: 0 | G24: 0 | H24: 0 | I24: 20 | Q24: /Fin/
A25: <Source> | B25: Lorry 3 | C25: ? | D25: Lorry 3 | E25: Lorry 3 | F25: Lorry 3 | G25: Lorry 3 | H25: ? | I25: Account | Q25: /Fin/
Q26: /Fin/
A27: <Process> | B27: cordial (pallet) | C27: cordial (pallet) | D27: volume (pallet) | E27: weight (tonne) | F27: Time not used | G27: Time not used | H27: cost of cordial pallets storage | I27: cumulative result | Q27: /Fin/
A28: cordial unloading | B28: -1 | C28: =-B28 -> 1 | D28: =B28 -> -1 | E28: -0.5 | F28: -0.03 | G28: =-F28 -> 0.03 | H28: =-19*B28 -> 19 | I28: =-H28 -> -19 | Q28: /Fin/
A29: <Periode_Debut> | B29: 0 | C29: 0 | D29: 0 | E29: 0 | F29: 0 | G29: 1 | H29: 0 | I29: 0 | Q29: /Fin/
A30: <Periode_Prolongement> | B30: 0 | C30: 0 | D30: 0 | E30: 0 | F30: 0 | G30: 0 | H30: 0 | I30: 20 | Q30: /Fin/
A31: <Source> | B31: Lorry 3 | C31: ? | D31: Lorry 3 | E31: Lorry 3 | F31: Lorry 3 | G31: Lorry 3 | H31: ? | I31: Account | Q31: /Fin/
Q32: /Fin/
Q33: /Fin/
A34: <Etat des lieux> | B34: <Minimal> | C34: <Maximal> | D34: 0 | E34: 1 | F34: 2 | G34: 3 | H34: 4 | I34: 5 | J34: 6 | K34: 7 | L34: 8 | M34: 9 | N34: 10 | O34: 11 | P34: 12 | Q34: /Fin/
A35: nectar (pallet) | B35: 0 | C35: 1000000000 | E35: 0 | F35: 0 | Q35: /Fin/
A36: cordial (pallet) | B36: 0 | C36: 1000000000 | E36: 0 | F36: 0 | Q36: /Fin/
A37: volume (pallet) | B37: 0 | C37: 24 | E37: 0 | F37: 0 | Q37: /Fin/
A38: weight (tonne) | B38: 0 | C38: 15 | E38: 0 | F38: 0 | Q38: /Fin/
A39: distance (km) | B39: -1000000000 | C39: 1000000000 | E39: 6966 | F39: 9431 | G39: -9431 | Q39: /Fin/
A40: Time not used | B40: 0 | C40: 150 | D40: 150 | E40: 49.045714 | F40: 9.5114286 | G40: 140.48857 | Q40: /Fin/
...

Sheet Wharehouse1
A1: <Nom> | B1: Paris | E1: Période | F1: 1 | Q1: /Fin/
Q2: /Fin/
A3: <Process> | B3: nectar needs (pallet) | C3: nectar needs (pallet) | D3: nectar (pallet) | E3: nectar sales (pallet) | F3: nectar sales (pallet) | G3: nectar turnover | H3: nectar turnover | I3: cost of nectar pallets storage | J3: cumulative result | K3: cumulative result | Q3: /Fin/
A4: Demand of nectar | B4: 1 | C4: -1 | D4: -1 | E4: 1 | F4: -1 | G4: 1000 | H4: =-G4 -> -1000 | I4: -12 | J4: =G4 -> 1000 | K4: =-I4 -> 12 | Q4: /Fin/
A5: <Periode_Debut> | B5: 0 | C5: 1 | D5: 0 | E5: 0 | F5: 1 | G5: 0 | H5: 1 | I5: 0 | J5: 0 | K5: 0 | Q5: /Fin/
A6: <Periode_Prolongement> | B6: 0 | C6: 0 | D6: 0 | E6: 0 | F6: 0 | G6: 0 | H6: 0 | I6: 0 | J6: 0 | K6: 20 | Q6: /Fin/
A7: <Source> | B7: Paris | C7: Paris | D7: Paris | E7: Paris | F7: Paris | G7: Paris | H7: Paris | I7: Paris | J7: Account | K7: Account | Q7: /Fin/
Q8: /Fin/
A9: <Process> | B9: cordial needs (pallet) | C9: cordial needs (pallet) | D9: cordial (pallet) | E9: cordial sales (pallet) | F9: cordial sales (pallet) | G9: cordial turnover | H9: cordial turnover | I9: cost of cordial pallets storage | J9: cumulative result | K9: cumulative result | Q9: /Fin/
A10: Demand of cordial | B10: 1 | C10: -1 | D10: -1 | E10: 1 | F10: -1 | G10: 1600 | H10: =-G10 -> -1600 | I10: -19 | J10: =G10 -> 1600 | K10: =-I10 -> 19 | Q10: /Fin/
A11: <Periode_Debut> | B11: 0 | C11: 1 | D11: 0 | E11: 0 | F11: 1 | G11: 0 | H11: 1 | I11: 0 | J11: 0 | K11: 0 | Q11: /Fin/
A12: <Periode_Prolongement> | B12: 0 | C12: 0 | D12: 0 | E12: 0 | F12: 0 | G12: 0 | H12: 0 | I12: 0 | J12: 0 | K12: 20 | Q12: /Fin/
A13: <Source> | B13: Paris | C13: Paris | D13: Paris | E13: Paris | F13: Paris | G13: Paris | H13: Paris | I13: Paris | J13: Account | K13: Account | Q13: /Fin/
Q14: /Fin/
Q15: /Fin/
Q16: /Fin/
A17: <Etat des lieux> | B17: <Minimal> | C17: <Maximal> | D17: 0 | E17: 1 | F17: 2 | G17: 3 | H17: 4 | I17: 5 | J17: 6 | K17: 7 | L17: 8 | M17: 9 | N17: 10 | O17: 11 | P17: 12 | Q17: /Fin/
A18: nectar (pallet) | B18: 0 | C18: 750 | D18: 10 | E18: 0 | F18: 1 | Q18: /Fin/
A19: cordial (pallet) | B19: 0 | C19: 750 | D19: 10 | E19: 2 | F19: 41 | Q19: /Fin/
A20: nectar turnover | B20: -1000000000 | C20: 1000000000 | D20: 0 | E20: 20000 | F20: 22000 | G20: -22000 | Q20: /Fin/
A21: cordial turnover | B21: -1000000000 | C21: 1000000000 | D21: 0 | E21: 24000 | F21: 27200 | G21: -27200 | Q21: /Fin/
A22: cost of nectar pallets storage | B22: -1000000000 | C22: 1000000000 | E22: 0 | F22: 12 | Q22: /Fin/
A23: cost of cordial pallets storage | B23: -1000000000 | C23: 1000000000 | E23: 38 | F23: 779 | Q23: /Fin/
A24: nectar needs (pallet) | B24: -1000000000 | C24: 1000000000 | E24: 20 | F24: 22 | G24: -22 | Q24: /Fin/
A25: cordial needs (pallet) | B25: -1000000000 | C25: 1000000000 | E25: 15 | F25: 17 | G25: -17 | Q25: /Fin/
A26: nectar sales (pallet) | B26: -1000000000 | C26: 1000000000 | E26: 20 | F26: 22 | G26: -22 | Q26: /Fin/
A27: cordial sales (pallet) | B27: -1000000000 | C27: 1000000000 | E27: 15 | F27: 17 | G27: -17 | Q27: /Fin/
Q28: /Fin/
A29: /Fin/ | B29: /Fin/ | C29: /Fin/ | D29: /Fin/ | E29: /Fin/ | F29: /Fin/ | G29: /Fin/ | H29: /Fin/ | I29: /Fin/ | J29: /Fin/ | K29: /Fin/ | L29: /Fin/ | M29: /Fin/ | N29: /Fin/ | O29: /Fin/ | P29: /Fin/ | Q29: /Fin/

Sheet Wharehouse2
A1: <Nom> | B1: Rauma | E1: Période | F1: 1 | Q1: /Fin/
Q2: /Fin/
A3: <Process> | B3: nectar needs (pallet) | C3: nectar needs (pallet) | D3: nectar (pallet) | E3: nectar sales (pallet) | F3: nectar sales (pallet) | G3: nectar turnover | H3: nectar turnover | I3: cost of nectar pallets storage | J3: cumulative result | K3: cumulative result | Q3: /Fin/
A4: Demand of nectar | B4: 1 | C4: -1 | D4: -1 | E4: 1 | F4: -1 | G4: 700 | H4: =-G4 -> -700 | I4: -12 | J4: =G4 -> 700 | K4: =-I4 -> 12 | Q4: /Fin/
A5: <Periode_Debut> | B5: 0 | C5: 1 | D5: 0 | E5: 0 | F5: 1 | G5: 0 | H5: 1 | I5: 0 | J5: 0 | K5: 0 | Q5: /Fin/
A6: <Periode_Prolongement> | B6: 0 | C6: 0 | D6: 0 | E6: 0 | F6: 0 | G6: 0 | H6: 0 | I6: 0 | J6: 0 | K6: 20 | Q6: /Fin/
A7: <Source> | B7: Rauma | C7: Rauma | D7: Rauma | E7: Rauma | F7: Rauma | G7: Rauma | H7: Rauma | I7: Rauma | J7: Account | K7: Account | Q7: /Fin/
Q8: /Fin/
A9: <Process> | B9: cordial needs (pallet) | C9: cordial needs (pallet) | D9: cordial (pallet) | E9: cordial sales (pallet) | F9: cordial sales (pallet) | G9: cordial turnover | H9: cordial turnover | I9: cost of cordial pallets storage | J9: cumulative result | K9: cumulative result | Q9: /Fin/
A10: Demand of cordial | B10: 1 | C10: -1 | D10: -1 | E10: 1 | F10: -1 | G10: 1300 | H10: =-G10 -> -1300 | I10: -19 | J10: =G10 -> 1300 | K10: =-I10 -> 19 | Q10: /Fin/
A11: <Periode_Debut> | B11: 0 | C11: 1 | D11: 0 | E11: 0 | F11: 1 | G11: 0 | H11: 1 | I11: 0 | J11: 0 | K11: 0 | Q11: /Fin/
A12: <Periode_Prolongement> | B12: 0 | C12: 0 | D12: 0 | E12: 0 | F12: 0 | G12: 0 | H12: 0 | I12: 0 | J12: 0 | K12: 20 | Q12: /Fin/
A13: <Source> | B13: Rauma | C13: Rauma | D13: Rauma | E13: Rauma | F13: Rauma | G13: Rauma | H13: Rauma | I13: Rauma | J13: Account | K13: Account | Q13: /Fin/
Q14: /Fin/
Q15: /Fin/
Q16: /Fin/
A17: <Etat des lieux> | B17: <Minimal> | C17: <Maximal> | D17: 0 | E17: 1 | F17: 2 | G17: 3 | H17: 4 | I17: 5 | J17: 6 | K17: 7 | L17: 8 | M17: 9 | N17: 10 | O17: 11 | P17: 12 | Q17: /Fin/
A18: nectar (pallet) | B18: 0 | C18: 750 | D18: 10 | E18: 1 | F18: 69 | Q18: /Fin/
A19: cordial (pallet) | B19: 0 | C19: 750 | D19: 10 | E19: 2 | F19: 2 | Q19: /Fin/
A20: nectar turnover | B20: -1000000000 | C20: 1000000000 | D20: 0 | E20: 14000 | F20: 15400 | G20: -15400 | Q20: /Fin/
A21: cordial turnover | B21: -1000000000 | C21: 1000000000 | D21: 0 | E21: 18200 | F21: 22100 | G21: -22100 | Q21: /Fin/
A22: cost of nectar pallets storage | B22: -1000000000 | C22: 1000000000 | E22: 12 | F22: 828 | Q22: /Fin/
A23: cost of cordial pallets storage | B23: -1000000000 | C23: 1000000000 | E23: 38 | F23: 38 | Q23: /Fin/
A24: nectar needs (pallet) | B24: -1000000000 | C24: 1000000000 | E24: 20 | F24: 22 | G24: -22
A25: cordial needs (pallet) | B25: -1000000000 | C25: 1000000000 | E25: 14 | F25: 17 | G25: -17 | Q25: /Fin/
A26: nectar sales (pallet) | B26: -1000000000 | C26: 1000000000 | E26: 20 | F26: 22 | G26: -22
A27: cordial sales (pallet) | B27: -1000000000 | C27: 1000000000 | E27: 14 | F27: 17 | G27: -17
Q28: /Fin/
A29: /Fin/ | B29: /Fin/ | C29: /Fin/ | D29: /Fin/ | E29: /Fin/ | F29: /Fin/ | G29: /Fin/ | H29: /Fin/ | I29: /Fin/ | J29: /Fin/ | K29: /Fin/ | L29: /Fin/ | M29: /Fin/ | N29: /Fin/ | O29: /Fin/ | P29: /Fin/ | Q29: /Fin/

Sheet Wharehouse3
A1: <Nom> | B1: Madrid | E1: Période | F1: 1 | Q1: /Fin/
Q2: /Fin/
A3: <Process> | B3: nectar needs (pallet) | C3: nectar needs (pallet) | D3: nectar (pallet) | E3: nectar sales (pallet) | F3: nectar sales (pallet) | G3: nectar turnover | H3: nectar turnover | I3: cost of nectar pallets storage | J3: cumulative result | K3: cumulative result | Q3: /Fin/
A4: Demand of nectar | B4: 1 | C4: -1 | D4: -1 | E4: 1 | F4: -1 | G4: 900 | H4: =-G4 -> -900 | I4: -12 | J4: =G4 -> 900 | K4: =-I4 -> 12 | Q4: /Fin/
A5: <Periode_Debut> | B5: 0 | C5: 1 | D5: 0 | E5: 0 | F5: 1 | G5: 0 | H5: 1 | I5: 0 | J5: 0 | K5: 0 | Q5: /Fin/
A6: <Periode_Prolongement> | B6: 0 | C6: 0 | D6: 0 | E6: 0 | F6: 0 | G6: 0 | H6: 0 | I6: 0 | J6: 0 | K6: 20 | Q6: /Fin/
A7: <Source> | B7: Madrid | C7: Madrid | D7: Madrid | E7: Madrid | F7: Madrid | G7: Madrid | H7: Madrid | I7: Madrid | J7: Account | K7: Account | Q7: /Fin/
Q8: /Fin/
A9: <Process> | B9: cordial needs (pallet) | C9: cordial needs (pallet) | D9: cordial (pallet) | E9: cordial sales (pallet) | F9: cordial sales (pallet) | G9: cordial turnover | H9: cordial turnover | I9: cost of cordial pallets storage | J9: cumulative result | K9: cumulative result | Q9: /Fin/
A10: Demand of cordial | B10: 1 | C10: -1 | D10: -1 | E10: 1 | F10: -1 | G10: 1500 | H10: =-G10 -> -1500 | I10: -19 | J10: =G10 -> 1500 | K10: =-I10 -> 19 | Q10: /Fin/
A11: <Periode_Debut> | B11: 0 | C11: 1 | D11: 0 | E11: 0 | F11: 1 | G11: 0 | H11: 1 | I11: 0 | J11: 0 | K11: 0 | Q11: /Fin/
A12: <Periode_Prolongement> | B12: 0 | C12: 0 | D12: 0 | E12: 0 | F12: 0 | G12: 0 | H12: 0 | I12: 0 | J12: 0 | K12: 20 | Q12: /Fin/
A13: <Source> | B13: Madrid | C13: Madrid | D13: Madrid | E13: Madrid | F13: Madrid | G13: Madrid | H13: Madrid | I13: Madrid | J13: Account | K13: Account | Q13: /Fin/
Q14: /Fin/
Q15: /Fin/
Q16: /Fin/
A17: <Etat des lieux> | B17: <Minimal> | C17: <Maximal> | D17: 0 | E17: 1 | F17: 2 | G17: 3 | H17: 4 | I17: 5 | J17: 6 | K17: 7 | L17: 8 | M17: 9 | N17: 10 | O17: 11 | P17: 12 | Q17: /Fin/
A18: nectar (pallet) | B18: 0 | C18: 750 | D18: 10 | E18: 2 | F18: 55 | Q18: /Fin/
A19: cordial (pallet) | B19: 0 | C19: 750 | D19: 10 | E19: 0 | F19: 23 | Q19: /Fin/
A20: nectar turnover | B20: -1000000000 | C20: 1000000000 | D20: 0 | E20: 21600 | F20: 21600 | G20: -21600 | Q20: /Fin/
A21: cordial turnover | B21: -1000000000 | C21: 1000000000 | D21: 0 | E21: 21000 | F21: 19500 | G21: -19500 | Q21: /Fin/
A22: cost of nectar pallets storage | B22: -1000000000 | C22: 1000000000 | E22: 24 | F22: 660 | Q22: /Fin/
A23: cost of cordial pallets storage | B23: -1000000000 | C23: 1000000000 | E23: 0 | F23: 437 | Q23: /Fin/
A24: nectar needs (pallet) | B24: -1000000000 | C24: 1000000000 | E24: 24 | F24: 24 | G24: -24
A25: cordial needs (pallet) | B25: -1000000000 | C25: 1000000000 | E25: 14 | F25: 13 | G25: -13 | Q25: /Fin/
A26: nectar sales (pallet) | B26: -1000000000 | C26: 1000000000 | E26: 24 | F26: 24 | G26: -24
A27: cordial sales (pallet) | B27: -1000000000 | C27: 1000000000 | E27: 14 | F27: 13 | G27: -13
Q28: /Fin/
A29: /Fin/ | B29: /Fin/ | C29: /Fin/ | D29: /Fin/ | E29: /Fin/ | F29: /Fin/ | G29: /Fin/ | H29: /Fin/ | I29: /Fin/ | J29: /Fin/ | K29: /Fin/ | L29: /Fin/ | M29: /Fin/ | N29: /Fin/ | O29: /Fin/ | P29: /Fin/ | Q29: /Fin/

Sheet Wharehouse4
A1: <Nom> | B1: Milan | E1: Période | F1: 1 | Q1: /Fin/
Q2: /Fin/
A3: <Process> | B3: nectar needs (pallet) | C3: nectar needs (pallet) | D3: nectar (pallet) | E3: nectar sales (pallet) | F3: nectar sales (pallet) | G3: nectar turnover | H3: nectar turnover | I3: cost of nectar pallets storage | J3: cumulative result | K3: cumulative result | Q3: /Fin/
A4: Demand of nectar | B4: 1 | C4: -1 | D4: -1 | E4: 1 | F4: -1 | G4: 900 | H4: =-G4 -> -900 | I4: -12 | J4: =G4 -> 900 | K4: =-I4 -> 12 | Q4: /Fin/
A5: <Periode_Debut> | B5: 0 | C5: 1 | D5: 0 | E5: 0 | F5: 1 | G5: 0 | H5: 1 | I5: 0 | J5: 0 | K5: 0 | Q5: /Fin/
A6: <Periode_Prolongement> | B6: 0 | C6: 0 | D6: 0 | E6: 0 | F6: 0 | G6: 0 | H6: 0 | I6: 0 | J6: 0 | K6: 20 | Q6: /Fin/
A7: <Source> | B7: Milan | C7: Milan | D7: Milan | E7: Milan | F7: Milan | G7: Milan | H7: Milan | I7: Milan | J7: Account | K7: Account | Q7: /Fin/
Q8: /Fin/
A9: <Process> | B9: cordial needs (pallet) | C9: cordial needs (pallet) | D9: cordial (pallet) | E9: cordial sales (pallet) | F9: cordial sales (pallet) | G9: cordial turnover | H9: cordial turnover | I9: cost of cordial pallets storage | J9: cumulative result | K9: cumulative result | Q9: /Fin/
A10: Demand of cordial | B10: 1 | C10: -1 | D10: -1 | E10: 1 | F10: -1 | G10: 1500 | H10: =-G10 -> -1500 | I10: -19 | J10: =G10 -> 1500 | K10: =-I10 -> 19 | Q10: /Fin/
A11: <Periode_Debut> | B11: 0 | C11: 1 | D11: 0 | E11: 0 | F11: 1 | G11: 0 | H11: 1 | I11: 0 | J11: 0 | K11: 0 | Q11: /Fin/
A12: <Periode_Prolongement> | B12: 0 | C12: 0 | D12: 0 | E12: 0 | F12: 0 | G12: 0 | H12: 0 | I12: 0 | J12: 0 | K12: 20 | Q12: /Fin/
A13: <Source> | B13: Milan | C13: Milan | D13: Milan | E13: Milan | F13: Milan | G13: Milan | H13: Milan | I13: Milan | J13: Account | K13: Account | Q13: /Fin/
Q14: /Fin/
Q15: /Fin/
Q16: /Fin/
A17: <Etat des lieux> | B17: <Minimal> | C17: <Maximal> | D17: 0 | E17: 1 | F17: 2 | G17: 3 | H17: 4 | I17: 5 | J17: 6 | K17: 7 | L17: 8 | M17: 9 | N17: 10 | O17: 11 | P17: 12 | Q17: /Fin/
A18: nectar (pallet) | B18: 0 | C18: 750 | D18: 10 | E18: 11 | F18: 19 | Q18: /Fin/
A19: cordial (pallet) | B19: 0 | C19: 750 | D19: 10 | E19: 4 | F19: 12 | Q19: /Fin/
A20: nectar turnover | B20: -1000000000 | C20: 1000000000 | D20: 0 | E20: 19800 | F20: 19800 | G20: -19800 | Q20: /Fin/
A21: cordial turnover | B21: -1000000000 | C21: 1000000000 | D21: 0 | E21: 22500 | F21: 21000 | G21: -21000 | Q21: /Fin/
A22: cost of nectar pallets storage | B22: -1000000000 | C22: 1000000000 | E22: 132 | F22: 228 | Q22: /Fin/
A23: cost of cordial pallets storage | B23: -1000000000 | C23: 1000000000 | E23: 76 | F23: 228 | Q23: /Fin/
A24: nectar needs (pallet) | B24: -1000000000 | C24: 1000000000 | E24: 22 | F24: 22 | G24: -22
A25: cordial needs (pallet) | B25: -1000000000 | C25: 1000000000 | E25: 15 | F25: 14 | G25: -14 | Q25: /Fin/
A26: nectar sales (pallet) | B26: -1000000000 | C26: 1000000000 | E26: 22 | F26: 22 | G26: -22
A27: cordial sales (pallet) | B27: -1000000000 | C27: 1000000000 | E27: 15 | F27: 14 | G27: -14
Q28: /Fin/
A29: /Fin/ | B29: /Fin/ | C29: /Fin/ | D29: /Fin/ | E29: /Fin/ | F29: /Fin/ | G29: /Fin/ | H29: /Fin/ | I29: /Fin/ | J29: /Fin/ | K29: /Fin/ | L29: /Fin/ | M29: /Fin/ | N29: /Fin/ | O29: /Fin/ | P29: /Fin/ | Q29: /Fin/

Sheet Wharehouse5
A1: <Nom> | B1: Rome | E1: Période | F1: 1 | Q1: /Fin/
Q2: /Fin/
A3: <Process> | B3: nectar needs (pallet) | C3: nectar needs (pallet) | D3: nectar (pallet) | E3: nectar sales (pallet) | F3: nectar sales (pallet) | G3: nectar turnover | H3: nectar turnover | I3: cost of nectar pallets storage | J3: cumulative result | K3: cumulative result | Q3: /Fin/
A4: Demand of nectar | B4: 1 | C4: -1 | D4: -1 | E4: 1 | F4: -1 | G4: 1000 | H4: =-G4 -> -1000 | I4: -12 | J4: =G4 -> 1000 | K4: =-I4 -> 12 | Q4: /Fin/
A5: <Periode_Debut> | B5: 0 | C5: 1 | D5: 0 | E5: 0 | F5: 1 | G5: 0 | H5: 1 | I5: 0 | J5: 0 | K5: 0 | Q5: /Fin/
A6: <Periode_Prolongement> | B6: 0 | C6: 0 | D6: 0 | E6: 0 | F6: 0 | G6: 0 | H6: 0 | I6: 0 | J6: 0 | K6: 20 | Q6: /Fin/
A7: <Source> | B7: Rome | C7: Rome | D7: Rome | E7: Rome | F7: Rome | G7: Rome | H7: Rome | I7: Rome | J7: Account | K7: Account | Q7: /Fin/
Q8: /Fin/
A9: <Process> | B9: cordial needs (pallet) | C9: cordial needs (pallet) | D9: cordial (pallet) | E9: cordial sales (pallet) | F9: cordial sales (pallet) | G9: cordial turnover | H9: cordial turnover | I9: cost of cordial pallets storage | J9: cumulative result | K9: cumulative result | Q9: /Fin/
A10: Demand of cordial | B10: 1 | C10: -1 | D10: -1 | E10: 1 | F10: -1 | G10: 1600 | H10: =-G10 -> -1600 | I10: -19 | J10: =G10 -> 1600 | K10: =-I10 -> 19 | Q10: /Fin/
A11: <Periode_Debut> | B11: 0 | C11: 1 | D11: 0 | E11: 0 | F11: 1 | G11: 0 | H11: 1 | I11: 0 | J11: 0 | K11: 0 | Q11: /Fin/
A12: <Periode_Prolongement> | B12: 0 | C12: 0 | D12: 0 | E12: 0 | F12: 0 | G12: 0 | H12: 0 | I12: 0 | J12: 0 | K12: 20 | Q12: /Fin/
A13: <Source> | B13: Rome | C13: Rome | D13: Rome | E13: Rome | F13: Rome | G13: Rome | H13: Rome | I13: Rome | J13: Account | K13: Account | Q13: /Fin/
Q14: /Fin/
Q15: /Fin/
Q16: /Fin/
A17: <Etat des lieux> | B17: <Minimal> | C17: <Maximal> | D17: 0 | E17: 1 | F17: 2 | G17: 3 | H17: 4 | I17: 5 | J17: 6 | K17: 7 | L17: 8 | M17: 9 | N17: 10 | O17: 11 | P17: 12 | Q17: /Fin/
A18: nectar (pallet) | B18: 0 | C18: 750 | D18: 10 | E18: 0 | F18: 5 | Q18: /Fin/
A19: cordial (pallet) | B19: 0 | C19: 750 | D19: 10 | E19: 0 | F19: 8 | Q19: /Fin/
A20: nectar turnover | B20: -1000000000 | C20: 1000000000 | D20: 0 | E20: 27000 | F20: 26000 | G20: -26000 | Q20: /Fin/
A21: cordial turnover | B21: -1000000000 | C21: 1000000000 | D21: 0 | E21: 30400 | F21: 27200 | G21: -27200 | Q21: /Fin/
A22: cost of nectar pallets storage | B22: -1000000000 | C22: 1000000000 | E22: 0 | F22: 60 | Q22: /Fin/
A23: cost of cordial pallets storage | B23: -1000000000 | C23: 1000000000 | E23: 0 | F23: 152 | Q23: /Fin/
A24: nectar needs (pallet) | B24: -1000000000 | C24: 1000000000 | E24: 29 | F24: 26 | G24: -26
A25: cordial needs (pallet) | B25: -1000000000 | C25: 1000000000 | E25: 19 | F25: 17 | G25: -17 | Q25: /Fin/
A26: nectar sales (pallet) | B26: -1000000000 | C26: 1000000000 | E26: 27 | F26: 26 | G26: -26
A27: cordial sales (pallet) | B27: -1000000000 | C27: 1000000000 | E27: 19 | F27: 17 | G27: -17
Q28: /Fin/
A29: /Fin/ | B29: /Fin/ | C29: /Fin/ | D29: /Fin/ | E29: /Fin/ | F29: /Fin/ | G29: /Fin/ | H29: /Fin/ | I29: /Fin/ | J29: /Fin/ | K29: /Fin/ | L29: /Fin/ | M29: /Fin/ | N29: /Fin/ | O29: /Fin/ | P29: /Fin/ | Q29: /Fin/

Sheet Wharehouse6
A1: <Nom> | B1: Bucharest | E1: Période | F1: 1 | Q1: /Fin/
Q2: /Fin/
A3: <Process> | B3: nectar needs (pallet) | C3: nectar needs (pallet) | D3: nectar (pallet) | E3: nectar sales (pallet) | F3: nectar sales (pallet) | G3: nectar turnover | H3: nectar turnover | I3: cost of nectar pallets storage | J3: cumulative result | K3: cumulative result | Q3: /Fin/
A4: Demand of nectar | B4: 1 | C4: -1 | D4: -1 | E4: 1 | F4: -1 | G4: 600 | H4: =-G4 -> -600 | I4: -12 | J4: =G4 -> 600 | K4: =-I4 -> 12 | Q4: /Fin/
A5: <Periode_Debut> | B5: 0 | C5: 1 | D5: 0 | E5: 0 | F5: 1 | G5: 0 | H5: 1 | I5: 0 | J5: 0 | K5: 0 | Q5: /Fin/
A6: <Periode_Prolongement> | B6: 0 | C6: 0 | D6: 0 | E6: 0 | F6: 0 | G6: 0 | H6: 0 | I6: 0 | J6: 0 | K6: 20 | Q6: /Fin/
A7: <Source> | B7: Bucharest | C7: Bucharest | D7: Bucharest | E7: Bucharest | F7: Bucharest | G7: Bucharest | H7: Bucharest | I7: Bucharest | J7: Account | K7: Account | Q7: /Fin/
Q8: /Fin/
A9: <Process> | B9: cordial needs (pallet) | C9: cordial needs (pallet) | D9: cordial (pallet) | E9: cordial sales (pallet) | F9: cordial sales (pallet) | G9: cordial turnover | H9: cordial turnover | I9: cost of cordial pallets storage | J9: cumulative result | K9: cumulative result | Q9: /Fin/
A10: Demand of cordial | B10: 1 | C10: -1 | D10: -1 | E10: 1 | F10: -1 | G10: 1200 | H10: =-G10 -> -1200 | I10: -19 | J10: =G10 -> 1200 | K10: =-I10 -> 19 | Q10: /Fin/
A11: <Periode_Debut> | B11: 0 | C11: 1 | D11: 0 | E11: 0 | F11: 1 | G11: 0 | H11: 1 | I11: 0 | J11: 0 | K11: 0 | Q11: /Fin/
A12: <Periode_Prolongement> | B12: 0 | C12: 0 | D12: 0 | E12: 0 | F12: 0 | G12: 0 | H12: 0 | I12: 0 | J12: 0 | K12: 20 | Q12: /Fin/
A13: <Source> | B13: Bucharest | C13: Bucharest | D13: Bucharest | E13: Bucharest | F13: Bucharest | G13: Bucharest | H13: Bucharest | I13: Bucharest | J13: Account | K13: Account | Q13: /Fin/
Q14: /Fin/
Q15: /Fin/
Q16: /Fin/
A17: <Etat des lieux> | B17: <Minimal> | C17: <Maximal> | D17: 0 | E17: 1 | F17: 2 | G17: 3 | H17: 4 | I17: 5 | J17: 6 | K17: 7 | L17: 8 | M17: 9 | N17: 10 | O17: 11 | P17: 12 | Q17: /Fin/
A18: nectar (pallet) | B18: 0 | C18: 750 | D18: 10 | E18: 3 | F18: 1 | Q18: /Fin/
A19: cordial (pallet) | B19: 0 | C19: 750 | D19: 10 | E19: 0 | F19: 3 | Q19: /Fin/
A20: nectar turnover | B20: -1000000000 | C20: 1000000000 | D20: 0 | E20: 9600 | F20: 10800 | G20: -10800 | Q20: /Fin/
A21: cordial turnover | B21: -1000000000 | C21: 1000000000 | D21: 0 | E21: 16800 | F21: 16800 | G21: -16800 | Q21: /Fin/
A22: cost of nectar pallets storage | B22: -1000000000 | C22: 1000000000 | E22: 36 | F22: 12 | Q22: /Fin/
A23: cost of cordial pallets storage | B23: -1000000000 | C23: 1000000000 | E23: 0 | F23: 57 | Q23: /Fin/
A24: nectar needs (pallet) | B24: -1000000000 | C24: 1000000000 | E24: 16 | F24: 18 | G24: -18
A25: cordial needs (pallet) | B25: -1000000000 | C25: 1000000000 | E25: 14 | F25: 14 | G25: -14 | Q25: /Fin/
A26: nectar sales (pallet) | B26: -1000000000 | C26: 1000000000 | E26: 16 | F26: 18 | G26: -18
A27: cordial sales (pallet) | B27: -1000000000 | C27: 1000000000 | E27: 14 | F27: 14 | G27: -14
Q28: /Fin/
A29: /Fin/ | B29: /Fin/ | C29: /Fin/ | D29: /Fin/ | E29: /Fin/ | F29: /Fin/ | G29: /Fin/ | H29: /Fin/ | I29: /Fin/ | J29: /Fin/ | K29: /Fin/ | L29: /Fin/ | M29: /Fin/ | N29: /Fin/ | O29: /Fin/ | P29: /Fin/ | Q29: /Fin/

Sheet Wharehouse7
A1: <Nom> | B1: Budapest | E1: Période | F1: 1 | Q1: /Fin/
Q2: /Fin/
A3: <Process> | B3: nectar needs (pallet) | C3: nectar needs (pallet) | D3: nectar (pallet) | E3: nectar sales (pallet) | F3: nectar sales (pallet) | G3: nectar turnover | H3: nectar turnover | I3: cost of nectar pallets storage | J3: cumulative result | K3: cumulative result | Q3: /Fin/
A4: Demand of nectar | B4: 1 | C4: -1 | D4: -1 | E4: 1 | F4: -1 | G4: 1100 | H4: =-G4 -> -1100 | I4: -12 | J4: =G4 -> 1100 | K4: =-I4 -> 12 | Q4: /Fin/
A5: <Periode_Debut> | B5: 0 | C5: 1 | D5: 0 | E5: 0 | F5: 1 | G5: 0 | H5: 1 | I5: 0 | J5: 0 | K5: 0 | Q5: /Fin/
A6: <Periode_Prolongement> | B6: 0 | C6: 0 | D6: 0 | E6: 0 | F6: 0 | G6: 0 | H6: 0 | I6: 0 | J6: 0 | K6: 20 | Q6: /Fin/
A7: <Source> | B7: Budapest | C7: Budapest | D7: Budapest | E7: Budapest | F7: Budapest | G7: Budapest | H7: Budapest | I7: Budapest | J7: Account | K7: Account | Q7: /Fin/
Q8: /Fin/
A9: <Process> | B9: cordial needs (pallet) | C9: cordial needs (pallet) | D9: cordial (pallet) | E9: cordial sales (pallet) | F9: cordial sales (pallet) | G9: cordial turnover | H9: cordial turnover | I9: cost of cordial pallets storage | J9: cumulative result | K9: cumulative result | Q9: /Fin/
A10: Demand of cordial | B10: 1 | C10: -1 | D10: -1 | E10: 1 | F10: -1 | G10: 1300 | H10: =-G10 -> -1300 | I10: -19 | J10: =G10 -> 1300 | K10: =-I10 -> 19 | Q10: /Fin/
A11: <Periode_Debut> | B11: 0 | C11: 1 | D11: 0 | E11: 0 | F11: 1 | G11: 0 | H11: 1 | I11: 0 | J11: 0 | K11: 0 | Q11: /Fin/
A12: <Periode_Prolongement> | B12: 0 | C12: 0 | D12: 0 | E12: 0 | F12: 0 | G12: 0 | H12: 0 | I12: 0 | J12: 0 | K12: 20 | Q12: /Fin/
A13: <Source> | B13: Budapest | C13: Budapest | D13: Budapest | E13: Budapest | F13: Budapest | G13: Budapest | H13: Budapest | I13: Budapest | J13: Account | K13: Account | Q13: /Fin/
Q14: /Fin/
Q15: /Fin/
Q16: /Fin/
A17: <Etat des lieux> | B17: <Minimal> | C17: <Maximal> | D17: 0 | E17: 1 | F17: 2 | G17: 3 | H17: 4 | I17: 5 | J17: 6 | K17: 7 | L17: 8 | M17: 9 | N17: 10 | O17: 11 | P17: 12 | Q17: /Fin/
A18: nectar (pallet) | B18: 0 | C18: 750 | D18: 10 | E18: 2 | F18: 49 | Q18: /Fin/
A19: cordial (pallet) | B19: 0 | C19: 750 | D19: 10 | E19: 0 | F19: 3 | Q19: /Fin/
A20: nectar turnover | B20: -1000000000 | C20: 1000000000 | D20: 0 | E20: 20900 | F20: 20900 | G20: -20900 | Q20: /Fin/
A21: cordial turnover | B21: -1000000000 | C21: 1000000000 | D21: 0 | E21: 26000 | F21: 23400 | G21: -23400 | Q21: /Fin/
A22: cost of nectar pallets storage | B22: -1000000000 | C22: 1000000000 | E22: 24 | F22: 588 | Q22: /Fin/
A23: cost of cordial pallets storage | B23: -1000000000 | C23: 1000000000 | E23: 0 | F23: 57 | Q23: /Fin/
A24: nectar needs (pallet) | B24: -1000000000 | C24: 1000000000 | E24: 19 | F24: 19 | G24: -19
A25: cordial needs (pallet) | B25: -1000000000 | C25: 1000000000 | E25: 20 | F25: 18 | G25: -18 | Q25: /Fin/
A26: nectar sales (pallet) | B26: -1000000000 | C26: 1000000000 | E26: 19 | F26: 19 | G26: -19
A27: cordial sales (pallet) | B27: -1000000000 | C27: 1000000000 | E27: 20 | F27: 18 | G27: -18
Q28: /Fin/
A29: /Fin/ | B29: /Fin/ | C29: /Fin/ | D29: /Fin/ | E29: /Fin/ | F29: /Fin/ | G29: /Fin/ | H29: /Fin/ | I29: /Fin/ | J29: /Fin/ | K29: /Fin/ | L29: /Fin/ | M29: /Fin/ | N29: /Fin/ | O29: /Fin/ | P29: /Fin/ | Q29: /Fin/

Sheet Wharehouse8
A1: <Nom> | B1: Kemijarvi | E1: Période | F1: 1 | Q1: /Fin/
Q2: /Fin/
A3: <Process> | B3: nectar needs (pallet) | C3: nectar needs (pallet) | D3: nectar (pallet) | E3: nectar sales (pallet) | F3: nectar sales (pallet) | G3: nectar turnover | H3: nectar turnover | I3: cost of nectar pallets storage | J3: cumulative result | K3: cumulative result | Q3: /Fin/
A4: Demand of nectar | B4: 1 | C4: -1 | D4: -1 | E4: 1 | F4: -1 | G4: 700 | H4: =-G4 -> -700 | I4: -12 | J4: =G4 -> 700 | K4: =-I4 -> 12 | Q4: /Fin/
A5: <Periode_Debut> | B5: 0 | C5: 1 | D5: 0 | E5: 0 | F5: 1 | G5: 0 | H5: 1 | I5: 0 | J5: 0 | K5: 0 | Q5: /Fin/
A6: <Periode_Prolongement> | B6: 0 | C6: 0 | D6: 0 | E6: 0 | F6: 0 | G6: 0 | H6: 0 | I6: 0 | J6: 0 | K6: 20 | Q6: /Fin/
A7: <Source> | B7: Kemijarvi | C7: Kemijarvi | D7: Kemijarvi | E7: Kemijarvi | F7: Kemijarvi | G7: Kemijarvi | H7: Kemijarvi | I7: Kemijarvi | J7: Account | K7: Account | Q7: /Fin/
Q8: /Fin/
A9: <Process> | B9: cordial needs (pallet) | C9: cordial needs (pallet) | D9: cordial (pallet) | E9: cordial sales (pallet) | F9: cordial sales (pallet) | G9: cordial turnover | H9: cordial turnover | I9: cost of cordial pallets storage | J9: cumulative result | K9: cumulative result | Q9: /Fin/
A10: Demand of cordial | B10: 1 | C10: -1 | D10: -1 | E10: 1 | F10: -1 | G10: 1300 | H10: =-G10 -> -1300 | I10: -19 | J10: =G10 -> 1300 | K10: =-I10 -> 19 | Q10: /Fin/
A11: <Periode_Debut> | B11: 0 | C11: 1 | D11: 0 | E11: 0 | F11: 1 | G11: 0 | H11: 1 | I11: 0 | J11: 0 | K11: 0 | Q11: /Fin/
A12: <Periode_Prolongement> | B12: 0 | C12: 0 | D12: 0 | E12: 0 | F12: 0 | G12: 0 | H12: 0 | I12: 0 | J12: 0 | K12: 20 | Q12: /Fin/
A13: <Source> | B13: Kemijarvi | C13: Kemijarvi | D13: Kemijarvi | E13: Kemijarvi | F13: Kemijarvi | G13: Kemijarvi | H13: Kemijarvi | I13: Kemijarvi | J13: Account | K13: Account | Q13: /Fin/
Q14: /Fin/
Q15: /Fin/
Q16: /Fin/
A17: <Etat des lieux> | B17: <Minimal> | C17: <Maximal> | D17: 0 | E17: 1 | F17: 2 | G17: 3 | H17: 4 | I17: 5 | J17: 6 | K17: 7 | L17: 8 | M17: 9 | N17: 10 | O17: 11 | P17: 12 | Q17: /Fin/
A18: nectar (pallet) | B18: 0 | C18: 750 | D18: 10 | E18: 0 | F18: 2 | Q18: /Fin/
A19: cordial (pallet) | B19: 0 | C19: 750 | D19: 10 | E19: 0 | F19: 3 | Q19: /Fin/
A20: nectar turnover | B20: -1000000000 | C20: 1000000000 | D20: 0 | E20: 11900 | F20: 11200 | G20: -11200 | Q20: /Fin/
A21: cordial turnover | B21: -1000000000 | C21: 1000000000 | D21: 0 | E21: 22100 | F21: 19500 | G21: -19500 | Q21: /Fin/
A22: cost of nectar pallets storage | B22: -1000000000 | C22: 1000000000 | E22: 0 | F22: 24 | Q22: /Fin/
A23: cost of cordial pallets storage | B23: -1000000000 | C23: 1000000000 | E23: 0 | F23: 57 | Q23: /Fin/
A24: nectar needs (pallet) | B24: -1000000000 | C24: 1000000000 | E24: 17 | F24: 16 | G24: -16
A25: cordial needs (pallet) | B25: -1000000000 | C25: 1000000000 | E25: 17 | F25: 15 | G25: -15 | Q25: /Fin/
A26: nectar sales (pallet) | B26: -1000000000 | C26: 1000000000 | E26: 17 | F26: 16 | G26: -16
A27: cordial sales (pallet) | B27: -1000000000 | C27: 1000000000 | E27: 17 | F27: 15 | G27: -15
Q28: /Fin/
A29: /Fin/ | B29: /Fin/ | C29: /Fin/ | D29: /Fin/ | E29: /Fin/ | F29: /Fin/ | G29: /Fin/ | H29: /Fin/ | I29: /Fin/ | J29: /Fin/ | K29: /Fin/ | L29: /Fin/ | M29: /Fin/ | N29: /Fin/ | O29: /Fin/ | P29: /Fin/ | Q29: /Fin/

Sheet Wharehouse9
A1: <Nom> | B1: Warsaw | E1: Période | F1: 1 | Q1: /Fin/
Q2: /Fin/
A3: <Process> | B3: nectar needs (pallet) | C3: nectar needs (pallet) | D3: nectar (pallet) | E3: nectar sales (pallet) | F3: nectar sales (pallet) | G3: nectar turnover | H3: nectar turnover | I3: cost of nectar pallets storage | J3: cumulative result | K3: cumulative result | Q3: /Fin/
A4: Demand of nectar | B4: 1 | C4: -1 | D4: -1 | E4: 1 | F4: -1 | G4: 800 | H4: =-G4 -> -800 | I4: -12 | J4: =G4 -> 800 | K4: =-I4 -> 12 | Q4: /Fin/
A5: <Periode_Debut> | B5: 0 | C5: 1 | D5: 0 | E5: 0 | F5: 1 | G5: 0 | H5: 1 | I5: 0 | J5: 0 | K5: 0 | Q5: /Fin/
A6: <Periode_Prolongement> | B6: 0 | C6: 0 | D6: 0 | E6: 0 | F6: 0 | G6: 0 | H6: 0 | I6: 0 | J6: 0 | K6: 20 | Q6: /Fin/
A7: <Source> | B7: Warsaw | C7: Warsaw | D7: Warsaw | E7: Warsaw | F7: Warsaw | G7: Warsaw | H7: Warsaw | I7: Warsaw | J7: Account | K7: Account | Q7: /Fin/
Q8: /Fin/
A9: <Process> | B9: cordial needs (pallet) | C9: cordial needs (pallet) | D9: cordial (pallet) | E9: cordial sales (pallet) | F9: cordial sales (pallet) | G9: cordial turnover | H9: cordial turnover | I9: cost of cordial pallets storage | J9: cumulative result | K9: cumulative result | Q9: /Fin/
A10: Demand of cordial | B10: 1 | C10: -1 | D10: -1 | E10: 1 | F10: -1 | G10: 1400 | H10: =-G10 -> -1400 | I10: -19 | J10: =G10 -> 1400 | K10: =-I10 -> 19 | Q10: /Fin/
A11: <Periode_Debut> | B11: 0 | C11: 1 | D11: 0 | E11: 0 | F11: 1 | G11: 0 | H11: 1 | I11: 0 | J11: 0 | K11: 0 | Q11: /Fin/
A12: <Periode_Prolongement> | B12: 0 | C12: 0 | D12: 0 | E12: 0 | F12: 0 | G12: 0 | H12: 0 | I12: 0 | J12: 0 | K12: 20 | Q12: /Fin/
A13: <Source> | B13: Warsaw | C13: Warsaw | D13: Warsaw | E13: Warsaw | F13: Warsaw | G13: Warsaw | H13: Warsaw | I13: Warsaw | J13: Account | K13: Account | Q13: /Fin/
Q14: /Fin/
Q15: /Fin/
Q16: /Fin/
